Workbook

Sheet Catalyst details
A1: Cathode Details | D1: Anode Details
A2: Preparation Date | B2: 46004 | D2: Preparation Date | E2: 46007
A3: Owner Name | B3: Flora Haun | D3: Owner Name | E3: Flora Haun
A4: Group Name | B4: CE-NECC | D4: Group Name | E4: CE-NECC
A5: Measured Mass Loading (mg/cm2) | B5: 1.1 | D5: Measured Mass Loading (mg/cm2) | E5: 1
A6: Bottle n# | B6: 5 | D6: Bottle n# | E6: 04_2024_100807-5771
A7: Already used in other experiment? (y/n) | B7: n | D7: Already used in other experiment? (y/n) | E7: n
A8: Remarks | D8: Remarks | E8: first use
A9: Recipe ID | B9: CR_Cu_SD_0001 | D9: Recipe ID | E9: AR_Ir_SD_0002
A12: Cathode Recipe | D12: Anode Recipe
A13: Recipe Name | B13: {=INDEX('Recipe Mappings'!H2:S21,ROW(A1),MATCH('Catalyst details'!B9,'Recipe Mappings'!H1:S1,0))} -> Cu 9% Nafion | D13: Recipe Name | E13: {=INDEX('Recipe Mappings'!B2:G21,ROW(A1),MATCH('Catalyst details'!E9,'Recipe Mappings'!B1:G1,0))} -> Ir on Titanium
A14: Element | B14: {=INDEX('Recipe Mappings'!H2:S21,ROW(A2),MATCH('Catalyst details'!B9,'Recipe Mappings'!H1:S1,0))} -> Cu | D14: Element | E14: {=INDEX('Recipe Mappings'!B2:G21,ROW(A2),MATCH('Catalyst details'!E9,'Recipe Mappings'!B1:G1,0))} -> Ir
A15: Element Mass (mg) | B15: {=INDEX('Recipe Mappings'!H2:S21,ROW(A3),MATCH('Catalyst details'!B9,'Recipe Mappings'!H1:S1,0))} -> 200 | D15: Element Mass (mg) | E15: {=INDEX('Recipe Mappings'!B2:G21,ROW(A3),MATCH('Catalyst details'!E9,'Recipe Mappings'!B1:G1,0))} -> 190
A16: Solvent 1 Type | B16: {=INDEX('Recipe Mappings'!H2:S21,ROW(A4),MATCH('Catalyst details'!B9,'Recipe Mappings'!H1:S1,0))} -> Isopropanol | D16: Solvent 1 Type | E16: {=INDEX('Recipe Mappings'!B2:G21,ROW(A4),MATCH('Catalyst details'!E9,'Recipe Mappings'!B1:G1,0))} -> H20
A17: Solvent 1 Volume (ml) | B17: {=INDEX('Recipe Mappings'!H2:S21,ROW(A5),MATCH('Catalyst details'!B9,'Recipe Mappings'!H1:S1,0))} -> 10 | D17: Solvent 1 Volume (ml) | E17: {=INDEX('Recipe Mappings'!B2:G21,ROW(A5),MATCH('Catalyst details'!E9,'Recipe Mappings'!B1:G1,0))} -> 4.75
A18: Solvent 2 Type | B18: {=INDEX('Recipe Mappings'!H2:S21,ROW(A6),MATCH('Catalyst details'!B9,'Recipe Mappings'!H1:S1,0))} -> H2O | D18: Solvent 2 Type | E18: {=INDEX('Recipe Mappings'!B2:G21,ROW(A6),MATCH('Catalyst details'!E9,'Recipe Mappings'!B1:G1,0))} -> Isopropanol
A19: Solvent 2 Volume (ml) | B19: {=INDEX('Recipe Mappings'!H2:S21,ROW(A7),MATCH('Catalyst details'!B9,'Recipe Mappings'!H1:S1,0))} -> 10 | D19: Solvent 2 Volume (ml) | E19: {=INDEX('Recipe Mappings'!B2:G21,ROW(A7),MATCH('Catalyst details'!E9,'Recipe Mappings'!B1:G1,0))} -> 4.75
A20: Ionomer 1 Type | B20: {=INDEX('Recipe Mappings'!H2:S21,ROW(A8),MATCH('Catalyst details'!B9,'Recipe Mappings'!H1:S1,0))} -> Nafion perfluorinated resin solution | D20: Ionomer 1 Type | E20: {=INDEX('Recipe Mappings'!B2:G21,ROW(A8),MATCH('Catalyst details'!E9,'Recipe Mappings'!B1:G1,0))} -> Sustanion XA-9 5% in Ethanol
A21: Ionomer 1 Mass (mg) | B21: {=INDEX('Recipe Mappings'!H2:S21,ROW(A9),MATCH('Catalyst details'!B9,'Recipe Mappings'!H1:S1,0))} -> 420 | D21: Ionomer 1 Mass (mg) | E21: {=INDEX('Recipe Mappings'!B2:G21,ROW(A9),MATCH('Catalyst details'!E9,'Recipe Mappings'!B1:G1,0))} -> 670
A22: Ionomer 2 Type | B22: {=INDEX('Recipe Mappings'!H2:S21,ROW(A10),MATCH('Catalyst details'!B9,'Recipe Mappings'!H1:S1,0))} | D22: Ionomer 2 Type | E22: {=INDEX('Recipe Mappings'!B2:G21,ROW(A10),MATCH('Catalyst details'!E9,'Recipe Mappings'!B1:G1,0))}
A23: Ionomer 2 Mass (mg) | B23: {=INDEX('Recipe Mappings'!H2:S21,ROW(A11),MATCH('Catalyst details'!B9,'Recipe Mappings'!H1:S1,0))} | D23: Ionomer 2 Mass (mg) | E23: {=INDEX('Recipe Mappings'!B2:G21,ROW(A11),MATCH('Catalyst details'!E9,'Recipe Mappings'!B1:G1,0))}
A24: Deposition Method | B24: {=INDEX('Recipe Mappings'!H2:S21,ROW(A12),MATCH('Catalyst details'!B9,'Recipe Mappings'!H1:S1,0))} -> Spray Dep | D24: Deposition Method | E24: {=INDEX('Recipe Mappings'!B2:G21,ROW(A12),MATCH('Catalyst details'!E9,'Recipe Mappings'!B1:G1,0))} -> Spray Dep
A25: Deposition Temperature (°C) | B25: {=INDEX('Recipe Mappings'!H2:S21,ROW(A13),MATCH('Catalyst details'!B9,'Recipe Mappings'!H1:S1,0))} -> 185 | D25: Deposition Temperature (°C) | E25: {=INDEX('Recipe Mappings'!B2:G21,ROW(A13),MATCH('Catalyst details'!E9,'Recipe Mappings'!B1:G1,0))} -> 180
A26: N2 Deposition Pressure (bar) | B26: {=INDEX('Recipe Mappings'!H2:S21,ROW(A14),MATCH('Catalyst details'!B9,'Recipe Mappings'!H1:S1,0))} -> 2 | D26: N2 Deposition Pressure (bar) | E26: {=INDEX('Recipe Mappings'!B2:G21,ROW(A14),MATCH('Catalyst details'!E9,'Recipe Mappings'!B1:G1,0))} -> 2
A27: Substrate | B27: {=INDEX('Recipe Mappings'!H2:S21,ROW(A15),MATCH('Catalyst details'!B9,'Recipe Mappings'!H1:S1,0))} -> Freudenberg H23C6 | D27: Substrate | E27: {=INDEX('Recipe Mappings'!B2:G21,ROW(A15),MATCH('Catalyst details'!E9,'Recipe Mappings'!B1:G1,0))} -> Titanium
A28: Substrate Dimension | B28: {=INDEX('Recipe Mappings'!H2:S21,ROW(A16),MATCH('Catalyst details'!B9,'Recipe Mappings'!H1:S1,0))} -> 14 x 4 | D28: Substrate Dimension | E28: {=INDEX('Recipe Mappings'!B2:G21,ROW(A16),MATCH('Catalyst details'!E9,'Recipe Mappings'!B1:G1,0))} -> frit
A29: Substrate Total Area (cm²) | B29: {=INDEX('Recipe Mappings'!H2:S21,ROW(A17),MATCH('Catalyst details'!B9,'Recipe Mappings'!H1:S1,0))} -> 54 | D29: Substrate Total Area (cm²) | E29: {=INDEX('Recipe Mappings'!B2:G21,ROW(A17),MATCH('Catalyst details'!E9,'Recipe Mappings'!B1:G1,0))}
A30: Substrate Cleaning | B30: {=INDEX('Recipe Mappings'!H2:S21,ROW(A18),MATCH('Catalyst details'!B9,'Recipe Mappings'!H1:S1,0))} | D30: Substrate Cleaning | E30: {=INDEX('Recipe Mappings'!B2:G21,ROW(A18),MATCH('Catalyst details'!E9,'Recipe Mappings'!B1:G1,0))}
A31: Mass Loading (mg/cm2) | B31: {=INDEX('Recipe Mappings'!H2:S21,ROW(A19),MATCH('Catalyst details'!B9,'Recipe Mappings'!H1:S1,0))} -> 1 | D31: Mass Loading (mg/cm2) | E31: {=INDEX('Recipe Mappings'!B2:G21,ROW(A19),MATCH('Catalyst details'!E9,'Recipe Mappings'!B1:G1,0))}
A32: Recipe Remarks | B32: {=INDEX('Recipe Mappings'!H2:S21,ROW(A20),MATCH('Catalyst details'!B9,'Recipe Mappings'!H1:S1,0))} | D32: Recipe Remarks | E32: {=INDEX('Recipe Mappings'!B2:G21,ROW(A20),MATCH('Catalyst details'!E9,'Recipe Mappings'!B1:G1,0))}
A34: Browse NOMAD Recipe IDs
A35: https://nomad-hzb-ce.de/nomad-oasis/gui/upload/id/ZAhi-HGrQbu7ccrEkl_jaw
A41: Deposition methods | B41: Representation in ID
A42: Spray Dep | B42: SD
A43: Ultrasonic Nozzle | B43: UN
A44: Dropcast | B44: DC

Sheet Experimental details
B1: Please enter your data in this column | D1: Example Data
A2: Experiment Name | B2: 20260119_ZG_0p05MLiOH_Cu0p9pctNaf_Ir_800mA_CO_ref_CStil1A_liquid_aliquots
A3: User Name | B3: Flora Haun
A4: Cell type | B4: Zero-Gap | D4: Zero-Gap
A5: Reference Electrode (y/n) | B5: y | D5: y
A6: Reference Electrode Type | B6: Ag/AgCl | D6: Ag/AgCl
A7: Derivation with Motherelectrode (Ag/AgCl) [mV] | B7: 10
A8: Cathode Geometric Area (cm²) | B8: 8 | D8: 8
A9: Membrane Type | B9: AEM | D9: AEM
A10: Membrane Name | B10: PiperION | D10: PiperION
A11: Membrane Thickness (µm) | B11: 40 | D11: 40
A12: Membrane Remarks | B12: Activated in LiOH
A13: Gasket Thickness (µm) | B13: 11 | D13: 11
A14: Anolyte Type | B14: LiOH | D14: LiOH
A15: Anolyte Conc. (M) | B15: 0.05 | D15: 0.05
A16: Anolyte Flow Rate (ml/min) | B16: 11.6 | D16: 11.6
A17: Anolyte Volume (ml) | B17: 25 | D17: 25
A18: Humidifier (y/n) | B18: n | D18: n
A19: Humidifier Temperature (°C)
A20: Water Trap Volume (ml) | B20: 10 | D20: 10
A21: Feed Gas 1 | B21: CO | D21: CO
A22: Feed Gas Flow Rate 1 (ml/min) | B22: 30 | D22: 30
A23: Feed Gas 2
A24: Feed Gas Flow Rate 2 (ml/min)
A25: Bleedline Flow Rate (ml/min) | B25: 10 | D25: 10
A26: Nitrogen Start Value (ppm) | B26: 246222 | D26: 244522
A27: pH measured | B27: y | D27: yes
A28: CP/CA | B28: CP | D28: CP
A29: EC Seq start time | B29: 0.45392361 | D29: 0.54546296
A30: Remarks | B30: liquid aliquots 1ml of anolyte at 30min, 60min, 90min and end (180min)
A31: Cathode ID
A32: Anode ID
A34: Browse NOMAD IDs
A35: Cathode IDs | B35: https://nomad-hzb-ce.de/nomad-oasis/gui/upload/id/IP-YgHuAT1u6c4kiGr4y_w
A36: Anode IDs | B36: https://nomad-hzb-ce.de/nomad-oasis/gui/upload/id/pjPLYsM6Q9Ctugh1gAWypA
B40: Cell Types
B41: Zero-Gap
B42: Catholyte Flow
B43: H-Cell
B45: Ref electrode types
...

Sheet Raw Data
A1: FID | Y1: TCD | AM1: Potentiostat | AU1: Thermocouple | BC1: PH
A2: Experiment name | B2: Date | C2: Time | D2: Gas type | E2: RT | F2: area | G2: ppm value | I2: Gas type | J2: RT | K2: area | L2: ppm value | N2: Gas type | O2: RT | P2: area | Q2: ppm value | S2: Gas type | T2: RT | U2: area | V2: ppm value | Y2: Experiment name | AB2: Gas type | AC2: RT | AD2: area | AE2: ppm value | AG2: Gas type | AH2: RT | AI2: area | AJ2: ppm value | AM2: time/s | AN2: Ewe-Ece/V | AO2: I/mA | AP2: dQ/C | AQ2: <Ece>/V | AR2: <Ewe/V> | AU2: C:\Users\CO2\Desktop\Sid\DAQ_FPC\231113_CO.WDH - 13/11/2023 09:48:39 | BC2: pH Time | BD2: pH | BE2: Start:10:43:33
A3: 260119_FID01.CHR | B3: 46041 | C3: 0.45048611 | D3: CO | E3: 0 | F3: 0 | G3: 0 | H3: ppm | I3: CH4 | J3: 0 | K3: 0 | L3: 0 | M3: ppm | N3: C2H4 | O3: 0 | P3: 0 | Q3: 0 | R3: ppm | S3: C2H6 | T3: 0 | U3: 0 | V3: 0 | W3: ppm | Y3: 260119_TCD01. | Z3: 46041 | AA3: 0.45048611 | AB3: H2 | AC3: 0 | AD3: 0 | AE3: 0 | AF3: ppm | AG3: N2 | AH3: 0 | AI3: 0 | AJ3: 0 | AK3: ppm | AM3: 01/19/2026 10:53:39.8540 | AN3: 2.9142356 | AO3: 800.17255 | AP3: 0 | AQ3: 0.13932566 | AR3: -2.77491 | AU3: Sample Rate: 100 | BC3: 0 | BD3: 12.273 | BG3: =(HOUR('Experimental details'!B29)*3600)+(MINUTE('Experimental details'!B29)*60)+SECOND('Experimental details'!B29) -> 39219
A4: 260119_FID02.CHR | B4: 46041 | C4: 0.46298611 | D4: CO | E4: 2.386 | F4: 5045.8497 | G4: 187280.24 | H4: ppm | I4: CH4 | J4: 3.406 | K4: 127.2688 | L4: 4608.6039 | M4: ppm | N4: C2H4 | O4: 9.62 | P4: 232.1655 | Q4: 4333.1607 | R4: ppm | S4: C2H6 | T4: 0 | U4: 0 | V4: 0 | W4: ppm | Y4: 260119_TCD02. | Z4: 46041 | AA4: 0.46298611 | AB4: H2 | AC4: 2.383 | AD4: 16998.971 | AE4: 45707.419 | AF4: ppm | AG4: N2 | AH4: 3.66 | AI4: 8467.6566 | AJ4: 374825.33 | AK4: ppm | AM4: 01/19/2026 10:53:40.3540 | AN4: 2.941045 | AO4: 799.98975 | AP4: 0.40002197 | AQ4: 0.13924535 | AR4: -2.8017998 | AU4: Date | AV4: Time Stamp Local | AW4: bar(g) | AX4: øC cathode | AY4: øC anode | AZ4: Chn 1 Events | BA4: Time | BC4: 0.00069444444 | BD4: 12.294 | BG4: =BG3+0.5 -> 39219.5 | BH4: potential | BI4: current | BJ4: row | BL4: avg current | BM4: avg pot
A5: 260119_FID03.CHR | B5: 46041 | C5: 0.47548611 | D5: CO | E5: 2.39 | F5: 5387.8483 | G5: 199973.76 | H5: ppm | I5: CH4 | J5: 3.41 | K5: 19.6656 | L5: 712.1224 | M5: ppm | N5: C2H4 | O5: 9.563 | P5: 598.8018 | Q5: 11176.098 | R5: ppm | S5: C2H6 | T5: 0 | U5: 0 | V5: 0 | W5: ppm | Y5: 260119_TCD03. | Z5: 46041 | AA5: 0.47548611 | AB5: H2 | AC5: 2.38 | AD5: 14156.623 | AE5: 37833.812 | AF5: ppm | AG5: N2 | AH5: 3.716 | AI5: 5756.9371 | AJ5: 254833.89 | AK5: ppm | AM5: 01/19/2026 10:53:40.8540 | AN5: 2.9826078 | AO5: 800.06592 | AP5: 0.80004251 | AQ5: 0.13912776 | AR5: -2.8434801 | BA5: =(HOUR(AV5)*3600)+(MINUTE(AV5)*60)+SECOND(AV5) -> 0 | BC5: 0.0013888889 | BD5: 12.297 | BG5: =BG4+0.5 -> 39220 | BH5: =LOOKUP(Results!$D2,'Raw Data'!BG:BG,'Raw Data'!AN:AN) -> #N/A | BI5: =LOOKUP(Results!$D2,'Raw Data'!BG:BG,'Raw Data'!AO:AO) -> #N/A | BJ5: =LOOKUP(Results!$D2,'Raw Data'!BG:BG,ROW('Raw Data'!AO:AO)) -> #N/A | BK5: 40 | BL5: =AVERAGE(INDIRECT("$AO"&$BJ5&":$AO"&($BJ5-$BK$5))) -> #N/A | BM5: =AVERAGE(INDIRECT("$AN"&$BJ5&":$AN"&($BJ5-$BK$5))) -> #N/A
A6: 260119_FID04.CHR | B6: 46041 | C6: 0.48798611 | D6: CO | E6: 2.376 | F6: 5458.6802 | G6: 202602.73 | H6: ppm | I6: CH4 | J6: 0 | K6: 0 | L6: 0 | M6: ppm | N6: C2H4 | O6: 9.55 | P6: 711.8604 | Q6: 13286.235 | R6: ppm | S6: C2H6 | T6: 0 | U6: 0 | V6: 0 | W6: ppm | Y6: 260119_TCD04. | Z6: 46041 | AA6: 0.48798611 | AB6: H2 | AC6: 2.38 | AD6: 11307.153 | AE6: 29940.476 | AF6: ppm | AG6: N2 | AH6: 3.726 | AI6: 5673.918 | AJ6: 251159 | AK6: ppm | AM6: 01/19/2026 10:53:41.3540 | AN6: 3.0091155 | AO6: 799.95929 | AP6: 1.2000602 | AQ6: 0.13901831 | AR6: -2.8700972 | BA6: =(HOUR(AV6)*3600)+(MINUTE(AV6)*60)+SECOND(AV6) -> 0 | BC6: 0.0020833333 | BD6: 12.287 | BG6: =BG5+0.5 -> 39220.5 | BH6: =LOOKUP(Results!$D3,'Raw Data'!BG:BG,'Raw Data'!AN:AN) -> 3.4918752 | BI6: =LOOKUP(Results!$D3,'Raw Data'!BG:BG,'Raw Data'!AO:AO) -> 800.12689 | BJ6: =LOOKUP(Results!$D3,'Raw Data'!BG:BG,ROW('Raw Data'!AO:AO)) -> 1569 | BL6: =AVERAGE(INDIRECT("$AO"&$BJ6&":$AO"&($BJ6-$BK$5))) -> 800.17403 | BM6: =AVERAGE(INDIRECT("$AN"&$BJ6&":$AN"&($BJ6-$BK$5))) -> 3.4915945
A7: 260119_FID05.CHR | B7: 46041 | C7: 0.50049769 | D7: CO | E7: 2.373 | F7: 5384.693 | G7: 199856.64 | H7: ppm | I7: CH4 | J7: 0 | K7: 0 | L7: 0 | M7: ppm | N7: C2H4 | O7: 9.55 | P7: 729.1407 | Q7: 13608.757 | R7: ppm | S7: C2H6 | T7: 0 | U7: 0 | V7: 0 | W7: ppm | Y7: 260119_TCD05. | Z7: 46041 | AA7: 0.50049769 | AB7: H2 | AC7: 2.38 | AD7: 11495.091 | AE7: 30461.085 | AF7: ppm | AG7: N2 | AH7: 3.726 | AI7: 5648.1024 | AJ7: 250016.26 | AK7: ppm | AM7: 01/19/2026 10:53:41.8540 | AN7: 3.0210414 | AO7: 800.14203 | AP7: 1.6000769 | AQ7: 0.13892178 | AR7: -2.8821197 | BA7: =(HOUR(AV7)*3600)+(MINUTE(AV7)*60)+SECOND(AV7) -> 0 | BC7: 0.0027777778 | BD7: 12.259 | BG7: =BG6+0.5 -> 39221 | BH7: =LOOKUP(Results!$D4,'Raw Data'!BG:BG,'Raw Data'!AN:AN) -> 3.511754 | BI7: =LOOKUP(Results!$D4,'Raw Data'!BG:BG,'Raw Data'!AO:AO) -> 800.05066 | BJ7: =LOOKUP(Results!$D4,'Raw Data'!BG:BG,ROW('Raw Data'!AO:AO)) -> 3729 | BL7: =AVERAGE(INDIRECT("$AO"&$BJ7&":$AO"&($BJ7-$BK$5))) -> 800.07781 | BM7: =AVERAGE(INDIRECT("$AN"&$BJ7&":$AN"&($BJ7-$BK$5))) -> 3.5121554
A8: 260119_FID06.CHR | B8: 46041 | C8: 0.51299769 | D8: CO | E8: 2.373 | F8: 5333.5604 | G8: 197958.82 | H8: ppm | I8: CH4 | J8: 0 | K8: 0 | L8: 0 | M8: ppm | N8: C2H4 | O8: 9.55 | P8: 721.3228 | Q8: 13462.843 | R8: ppm | S8: C2H6 | T8: 0 | U8: 0 | V8: 0 | W8: ppm | Y8: 260119_TCD06. | Z8: 46041 | AA8: 0.51299769 | AB8: H2 | AC8: 2.383 | AD8: 12377.429 | AE8: 32905.255 | AF8: ppm | AG8: N2 | AH8: 3.73 | AI8: 5617.791 | AJ8: 248674.51 | AK8: ppm | AM8: 01/19/2026 10:53:42.3540 | AN8: 3.0195003 | AO8: 800.05072 | AP8: 2.0000913 | AQ8: 0.13883483 | AR8: -2.8806653 | BC8: 0.0034722222 | BD8: 12.244 | BG8: =BG7+0.5 -> 39221.5 | BH8: =LOOKUP(Results!$D5,'Raw Data'!BG:BG,'Raw Data'!AN:AN) -> 3.4749885 | BI8: =LOOKUP(Results!$D5,'Raw Data'!BG:BG,'Raw Data'!AO:AO) -> 800.11157 | BJ8: =LOOKUP(Results!$D5,'Raw Data'!BG:BG,ROW('Raw Data'!AO:AO)) -> 5889 | BL8: =AVERAGE(INDIRECT("$AO"&$BJ8&":$AO"&($BJ8-$BK$5))) -> 800.21341 | BM8: =AVERAGE(INDIRECT("$AN"&$BJ8&":$AN"&($BJ8-$BK$5))) -> 3.4752615
A9: 260119_FID07.CHR | B9: 46041 | C9: 0.52549769 | D9: CO | E9: 2.39 | F9: 5295.2925 | G9: 196538.48 | H9: ppm | I9: CH4 | J9: 0 | K9: 0 | L9: 0 | M9: ppm | N9: C2H4 | O9: 9.563 | P9: 714.4232 | Q9: 13334.068 | R9: ppm | S9: C2H6 | T9: 0 | U9: 0 | V9: 0 | W9: ppm | Y9: 260119_TCD07. | Z9: 46041 | AA9: 0.52549769 | AB9: H2 | AC9: 2.373 | AD9: 13234.384 | AE9: 35279.112 | AF9: ppm | AG9: N2 | AH9: 3.72 | AI9: 5605.3366 | AJ9: 248123.21 | AK9: ppm | AM9: 01/19/2026 10:53:42.8540 | AN9: 3.0176146 | AO9: 800.03546 | AP9: 2.4000988 | AQ9: 0.13877341 | AR9: -2.8788412 | BC9: 0.0041666667 | BD9: 12.233 | BG9: =BG8+0.5 -> 39222 | BH9: =LOOKUP(Results!$D6,'Raw Data'!BG:BG,'Raw Data'!AN:AN) -> 3.464951 | BI9: =LOOKUP(Results!$D6,'Raw Data'!BG:BG,'Raw Data'!AO:AO) -> 800.08118 | BJ9: =LOOKUP(Results!$D6,'Raw Data'!BG:BG,ROW('Raw Data'!AO:AO)) -> 8051 | BL9: =AVERAGE(INDIRECT("$AO"&$BJ9&":$AO"&($BJ9-$BK$5))) -> 800.05106 | BM9: =AVERAGE(INDIRECT("$AN"&$BJ9&":$AN"&($BJ9-$BK$5))) -> 3.4649592
A10: 260119_FID08.CHR | B10: 46041 | C10: 0.53799769 | D10: CO | E10: 2.39 | F10: 5268.4623 | G10: 195542.66 | H10: ppm | I10: CH4 | J10: 0 | K10: 0 | L10: 0 | M10: ppm | N10: C2H4 | O10: 9.56 | P10: 703.3832 | Q10: 13128.016 | R10: ppm | S10: C2H6 | T10: 0 | U10: 0 | V10: 0 | W10: ppm | Y10: 260119_TCD08. | Z10: 46041 | AA10: 0.53799769 | AB10: H2 | AC10: 2.39 | AD10: 14148.209 | AE10: 37810.504 | AF10: ppm | AG10: N2 | AH10: 3.726 | AI10: 5549.4047 | AJ10: 245647.36 | AK10: ppm | AM10: 01/19/2026 10:53:43.3540 | AN10: 3.0180819 | AO10: 799.74603 | AP10: 2.8001041 | AQ10: 0.1387466 | AR10: -2.8793354 | BC10: 0.0048611111 | BD10: 12.221 | BG10: =BG9+0.5 -> 39222.5 | BH10: =LOOKUP(Results!$D7,'Raw Data'!BG:BG,'Raw Data'!AN:AN) -> 3.465241 | BI10: =LOOKUP(Results!$D7,'Raw Data'!BG:BG,'Raw Data'!AO:AO) -> 799.95935 | BJ10: =LOOKUP(Results!$D7,'Raw Data'!BG:BG,ROW('Raw Data'!AO:AO)) -> 10211 | BL10: =AVERAGE(INDIRECT("$AO"&$BJ10&":$AO"&($BJ10-$BK$5))) -> 800.01689 | BM10: =AVERAGE(INDIRECT("$AN"&$BJ10&":$AN"&($BJ10-$BK$5))) -> 3.4647597
A11: 260119_FID09.CHR | B11: 46041 | C11: 0.55049769 | D11: CO | E11: 2.376 | F11: 5209.9978 | G11: 193372.71 | H11: ppm | I11: CH4 | J11: 0 | K11: 0 | L11: 0 | M11: ppm | N11: C2H4 | O11: 9.556 | P11: 676.294 | Q11: 12622.421 | R11: ppm | S11: C2H6 | T11: 0 | U11: 0 | V11: 0 | W11: ppm | Y11: 260119_TCD09. | Z11: 46041 | AA11: 0.55049769 | AB11: H2 | AC11: 2.396 | AD11: 15286.346 | AE11: 40963.263 | AF11: ppm | AG11: N2 | AH11: 3.73 | AI11: 5537.9709 | AJ11: 245141.23 | AK11: ppm | AM11: 01/19/2026 10:53:43.8540 | AN11: 3.0178909 | AO11: 800.14203 | AP11: 3.2001133 | AQ11: 0.13874179 | AR11: -2.8791492 | BC11: 0.0055555556 | BD11: 12.212 | BG11: =BG10+0.5 -> 39223 | BH11: =LOOKUP(Results!$D8,'Raw Data'!BG:BG,'Raw Data'!AN:AN) -> 3.468261 | BI11: =LOOKUP(Results!$D8,'Raw Data'!BG:BG,'Raw Data'!AO:AO) -> 800.20306 | BJ11: =LOOKUP(Results!$D8,'Raw Data'!BG:BG,ROW('Raw Data'!AO:AO)) -> 12371 | BL11: =AVERAGE(INDIRECT("$AO"&$BJ11&":$AO"&($BJ11-$BK$5))) -> 800.12648 | BM11: =AVERAGE(INDIRECT("$AN"&$BJ11&":$AN"&($BJ11-$BK$5))) -> 3.4678321
A12: 260119_FID10.CHR | B12: 46041 | C12: 0.56299769 | D12: CO | E12: 2.386 | F12: 5178.6594 | G12: 192209.56 | H12: ppm | I12: CH4 | J12: 0 | K12: 0 | L12: 0 | M12: ppm | N12: C2H4 | O12: 9.563 | P12: 654.9348 | Q12: 12223.77 | R12: ppm | S12: C2H6 | T12: 0 | U12: 0 | V12: 0 | W12: ppm | Y12: 260119_TCD10. | Z12: 46041 | AA12: 0.56299769 | AB12: H2 | AC12: 2.383 | AD12: 16728.415 | AE12: 44957.949 | AF12: ppm | AG12: N2 | AH12: 3.72 | AI12: 5501.2329 | AJ12: 243515.01 | AK12: ppm | AM12: 01/19/2026 10:53:44.3540 | AN12: 3.0169301 | AO12: 800.03552 | AP12: 3.6001172 | AQ12: 0.13874242 | AR12: -2.8781877 | BC12: 0.00625 | BD12: 12.202 | BG12: =BG11+0.5 -> 39223.5 | BH12: =LOOKUP(Results!$D9,'Raw Data'!BG:BG,'Raw Data'!AN:AN) -> 3.4824662 | BI12: =LOOKUP(Results!$D9,'Raw Data'!BG:BG,'Raw Data'!AO:AO) -> 800.05066 | BJ12: =LOOKUP(Results!$D9,'Raw Data'!BG:BG,ROW('Raw Data'!AO:AO)) -> 14531 | BL12: =AVERAGE(INDIRECT("$AO"&$BJ12&":$AO"&($BJ12-$BK$5))) -> 800.1406 | BM12: =AVERAGE(INDIRECT("$AN"&$BJ12&":$AN"&($BJ12-$BK$5))) -> 3.4823129
A13: 260119_FID11.CHR | B13: 46041 | C13: 0.57550926 | D13: CO | E13: 2.376 | F13: 5131.6875 | G13: 190466.17 | H13: ppm | I13: CH4 | J13: 0 | K13: 0 | L13: 0 | M13: ppm | N13: C2H4 | O13: 9.56 | P13: 608.0836 | Q13: 11349.335 | R13: ppm | S13: C2H6 | T13: 0 | U13: 0 | V13: 0 | W13: ppm | Y13: 260119_TCD11. | Z13: 46041 | AA13: 0.57550926 | AB13: H2 | AC13: 2.403 | AD13: 18791.497 | AE13: 50672.906 | AF13: ppm | AG13: N2 | AH13: 3.733 | AI13: 5431.5119 | AJ13: 240428.77 | AK13: ppm | AM13: 01/19/2026 10:53:44.8540 | AN13: 3.0163612 | AO13: 799.98975 | AP13: 4.0001235 | AQ13: 0.13873753 | AR13: -2.8776238 | BC13: 0.0069444444 | BD13: 12.193 | BG13: =BG12+0.5 -> 39224 | BH13: =LOOKUP(Results!$D10,'Raw Data'!BG:BG,'Raw Data'!AN:AN) -> 3.5080884 | BI13: =LOOKUP(Results!$D10,'Raw Data'!BG:BG,'Raw Data'!AO:AO) -> 800.20306 | BJ13: =LOOKUP(Results!$D10,'Raw Data'!BG:BG,ROW('Raw Data'!AO:AO)) -> 16691 | BL13: =AVERAGE(INDIRECT("$AO"&$BJ13&":$AO"&($BJ13-$BK$5))) -> 800.08376 | BM13: =AVERAGE(INDIRECT("$AN"&$BJ13&":$AN"&($BJ13-$BK$5))) -> 3.5081074
A14: 260119_FID12.CHR | B14: 46041 | C14: 0.58800926 | D14: CO | E14: 2.39 | F14: 5210.5264 | G14: 193392.33 | H14: ppm | I14: CH4 | J14: 0 | K14: 0 | L14: 0 | M14: ppm | N14: C2H4 | O14: 9.62 | P14: 201.8699 | Q14: 3767.7205 | R14: ppm | S14: C2H6 | T14: 0 | U14: 0 | V14: 0 | W14: ppm | Y14: 260119_TCD12. | Z14: 46041 | AA14: 0.58800926 | AB14: H2 | AC14: 2.356 | AD14: 7697.7984 | AE14: 19942.181 | AF14: ppm | AG14: N2 | AH14: 3.716 | AI14: 5607.2466 | AJ14: 248207.76 | AK14: ppm | AM14: 01/19/2026 10:53:45.3540 | AN14: 3.0174468 | AO14: 799.98975 | AP14: 4.4001331 | AQ14: 0.13873252 | AR14: -2.8787143 | BC14: 0.0076388889 | BD14: 12.185 | BG14: =BG13+0.5 -> 39224.5 | BH14: =LOOKUP(Results!$D11,'Raw Data'!BG:BG,'Raw Data'!AN:AN) -> 3.5572507 | BI14: =LOOKUP(Results!$D11,'Raw Data'!BG:BG,'Raw Data'!AO:AO) -> 800.15735 | BJ14: =LOOKUP(Results!$D11,'Raw Data'!BG:BG,ROW('Raw Data'!AO:AO)) -> 18851 | BL14: =AVERAGE(INDIRECT("$AO"&$BJ14&":$AO"&($BJ14-$BK$5))) -> 800.08598 | BM14: =AVERAGE(INDIRECT("$AN"&$BJ14&":$AN"&($BJ14-$BK$5))) -> 3.5565616
A15: 260119_FID13.CHR | B15: 46041 | C15: 0.60050926 | D15: CO | E15: 2.376 | F15: 5222.8042 | G15: 193848.03 | H15: ppm | I15: CH4 | J15: 0 | K15: 0 | L15: 0 | M15: ppm | N15: C2H4 | O15: 0 | P15: 0 | Q15: 0 | R15: ppm | S15: C2H6 | T15: 0 | U15: 0 | V15: 0 | W15: ppm | Y15: 260119_TCD13. | Z15: 46041 | AA15: 0.60050926 | AB15: H2 | AC15: 2.343 | AD15: 123.7736 | AE15: 0 | AF15: ppm | AG15: N2 | AH15: 3.723 | AI15: 5564.5117 | AJ15: 246316.08 | AK15: ppm | AM15: 01/19/2026 10:53:45.8540 | AN15: 3.0191369 | AO15: 799.92883 | AP15: 4.8001356 | AQ15: 0.13872437 | AR15: -2.8804126 | BC15: 0.0083333333 | BD15: 12.177 | BG15: =BG14+0.5 -> 39225 | BH15: =LOOKUP(Results!$D12,'Raw Data'!BG:BG,'Raw Data'!AN:AN) -> 3.5940108 | BI15: =LOOKUP(Results!$D12,'Raw Data'!BG:BG,'Raw Data'!AO:AO) -> 800.06592 | BJ15: =LOOKUP(Results!$D12,'Raw Data'!BG:BG,ROW('Raw Data'!AO:AO)) -> 20000 | BL15: =AVERAGE(INDIRECT("$AO"&$BJ15&":$AO"&($BJ15-$BK$5))) -> 800.1209 | BM15: =AVERAGE(INDIRECT("$AN"&$BJ15&":$AN"&($BJ15-$BK$5))) -> 3.5934131
A16: 260119_FID14.CHR | B16: 46041 | C16: 0.61300926 | D16: CO | E16: 2.39 | F16: 5220.6474 | G16: 193767.98 | H16: ppm | I16: CH4 | J16: 0 | K16: 0 | L16: 0 | M16: ppm | N16: C2H4 | O16: 0 | P16: 0 | Q16: 0 | R16: ppm | S16: C2H6 | T16: 0 | U16: 0 | V16: 0 | W16: ppm | Y16: 260119_TCD14. | Z16: 46041 | AA16: 0.61300926 | AB16: H2 | AC16: 0 | AD16: 0 | AE16: 0 | AF16: ppm | AG16: N2 | AH16: 3.713 | AI16: 5562.4012 | AJ16: 246222.65 | AK16: ppm | AM16: 01/19/2026 10:53:46.3540 | AN16: 3.0216427 | AO16: 800.06592 | AP16: 5.2001376 | AQ16: 0.13871731 | AR16: -2.8829253 | BC16: 0.0090277778 | BD16: 12.166 | BG16: =BG15+0.5 -> 39225.5 | BH16: =LOOKUP(Results!$D13,'Raw Data'!BG:BG,'Raw Data'!AN:AN) -> 3.5940108 | BI16: =LOOKUP(Results!$D13,'Raw Data'!BG:BG,'Raw Data'!AO:AO) -> 800.06592 | BJ16: =LOOKUP(Results!$D13,'Raw Data'!BG:BG,ROW('Raw Data'!AO:AO)) -> 20000 | BL16: =AVERAGE(INDIRECT("$AO"&$BJ16&":$AO"&($BJ16-$BK$5))) -> 800.1209 | BM16: =AVERAGE(INDIRECT("$AN"&$BJ16&":$AN"&($BJ16-$BK$5))) -> 3.5934131
AM17: 01/19/2026 10:53:46.8540 | AN17: 3.0244498 | AO17: 800.11157 | AP17: 5.6001472 | AQ17: 0.13871378 | AR17: -2.885736 | BC17: 0.0097222222 | BD17: 12.158 | BG17: =BG16+0.5 -> 39226 | BH17: =LOOKUP(Results!$D14,'Raw Data'!BG:BG,'Raw Data'!AN:AN) -> 3.5940108 | BI17: =LOOKUP(Results!$D14,'Raw Data'!BG:BG,'Raw Data'!AO:AO) -> 800.06592 | BJ17: =LOOKUP(Results!$D14,'Raw Data'!BG:BG,ROW('Raw Data'!AO:AO)) -> 20000 | BL17: =AVERAGE(INDIRECT("$AO"&$BJ17&":$AO"&($BJ17-$BK$5))) -> 800.1209 | BM17: =AVERAGE(INDIRECT("$AN"&$BJ17&":$AN"&($BJ17-$BK$5))) -> 3.5934131
AM18: 01/19/2026 10:53:47.3540 | AN18: 3.0271726 | AO18: 800.06592 | AP18: 6.0001478 | AQ18: 0.13870449 | AR18: -2.888468 | BC18: 0.010416667 | BD18: 12.149 | BG18: =BG17+0.5 -> 39226.5 | BH18: =LOOKUP(Results!$D15,'Raw Data'!BG:BG,'Raw Data'!AN:AN) -> 3.5940108 | BI18: =LOOKUP(Results!$D15,'Raw Data'!BG:BG,'Raw Data'!AO:AO) -> 800.06592 | BJ18: =LOOKUP(Results!$D15,'Raw Data'!BG:BG,ROW('Raw Data'!AO:AO)) -> 20000 | BL18: =AVERAGE(INDIRECT("$AO"&$BJ18&":$AO"&($BJ18-$BK$5))) -> 800.1209 | BM18: =AVERAGE(INDIRECT("$AN"&$BJ18&":$AN"&($BJ18-$BK$5))) -> 3.5934131
AM19: 01/19/2026 10:53:47.8540 | AN19: 3.02951 | AO19: 800.02026 | AP19: 6.4001498 | AQ19: 0.13870588 | AR19: -2.8908041 | BC19: 0.011111111 | BD19: 12.141 | BG19: =BG18+0.5 -> 39227 | BH19: =LOOKUP(Results!$D16,'Raw Data'!BG:BG,'Raw Data'!AN:AN) -> #N/A | BI19: =LOOKUP(Results!$D16,'Raw Data'!BG:BG,'Raw Data'!AO:AO) -> #N/A | BJ19: =LOOKUP(Results!$D16,'Raw Data'!BG:BG,ROW('Raw Data'!AO:AO)) -> #N/A | BL19: =AVERAGE(INDIRECT("$AO"&$BJ19&":$AO"&($BJ19-$BK$5))) -> #N/A | BM19: =AVERAGE(INDIRECT("$AN"&$BJ19&":$AN"&($BJ19-$BK$5))) -> #N/A
AM20: 01/19/2026 10:53:48.3540 | AN20: 3.0324068 | AO20: 799.85272 | AP20: 6.8001575 | AQ20: 0.13871031 | AR20: -2.8936965 | BC20: 0.011805556 | BD20: 12.134 | BG20: =BG19+0.5 -> 39227.5 | BH20: =LOOKUP(Results!$D17,'Raw Data'!BG:BG,'Raw Data'!AN:AN) -> #N/A | BI20: =LOOKUP(Results!$D17,'Raw Data'!BG:BG,'Raw Data'!AO:AO) -> #N/A | BJ20: =LOOKUP(Results!$D17,'Raw Data'!BG:BG,ROW('Raw Data'!AO:AO)) -> #N/A | BL20: =AVERAGE(INDIRECT("$AO"&$BJ20&":$AO"&($BJ20-$BK$5))) -> #N/A | BM20: =AVERAGE(INDIRECT("$AN"&$BJ20&":$AN"&($BJ20-$BK$5))) -> #N/A
AM21: 01/19/2026 10:53:48.8540 | AN21: 3.0349882 | AO21: 799.89832 | AP21: 7.2001638 | AQ21: 0.13871153 | AR21: -2.8962767 | BC21: 0.0125 | BD21: 12.126 | BG21: =BG20+0.5 -> 39228 | BH21: =LOOKUP(Results!$D18,'Raw Data'!BG:BG,'Raw Data'!AN:AN) -> #N/A | BI21: =LOOKUP(Results!$D18,'Raw Data'!BG:BG,'Raw Data'!AO:AO) -> #N/A | BJ21: =LOOKUP(Results!$D18,'Raw Data'!BG:BG,ROW('Raw Data'!AO:AO)) -> #N/A | BL21: =AVERAGE(INDIRECT("$AO"&$BJ21&":$AO"&($BJ21-$BK$5))) -> #N/A | BM21: =AVERAGE(INDIRECT("$AN"&$BJ21&":$AN"&($BJ21-$BK$5))) -> #N/A
AM22: 01/19/2026 10:53:49.3540 | AN22: 3.0379343 | AO22: 799.98975 | AP22: 7.6001611 | AQ22: 0.138721 | AR22: -2.8992133 | BC22: 0.013194444 | BD22: 12.12 | BG22: =BG21+0.5 -> 39228.5 | BH22: =LOOKUP(Results!$D19,'Raw Data'!BG:BG,'Raw Data'!AN:AN) -> #N/A | BI22: =LOOKUP(Results!$D19,'Raw Data'!BG:BG,'Raw Data'!AO:AO) -> #N/A | BJ22: =LOOKUP(Results!$D19,'Raw Data'!BG:BG,ROW('Raw Data'!AO:AO)) -> #N/A | BL22: =AVERAGE(INDIRECT("$AO"&$BJ22&":$AO"&($BJ22-$BK$5))) -> #N/A | BM22: =AVERAGE(INDIRECT("$AN"&$BJ22&":$AN"&($BJ22-$BK$5))) -> #N/A
AM23: 01/19/2026 10:53:49.8540 | AN23: 3.0408139 | AO23: 799.88318 | AP23: 8.0001602 | AQ23: 0.13873085 | AR23: -2.9020832 | BC23: 0.013888889 | BD23: 12.114 | BG23: =BG22+0.5 -> 39229
AM24: 01/19/2026 10:53:50.3540 | AN24: 3.0436919 | AO24: 799.92883 | AP24: 8.4001627 | AQ24: 0.13875049 | AR24: -2.9049413 | BC24: 0.014583333 | BD24: 12.107 | BG24: =BG23+0.5 -> 39229.5
AM25: 01/19/2026 10:53:50.8540 | AN25: 3.0457437 | AO25: 799.88318 | AP25: 8.8001595 | AQ25: 0.1387632 | AR25: -2.9069805 | BC25: 0.015277778 | BD25: 12.101 | BG25: =BG24+0.5 -> 39230
AM26: 01/19/2026 10:53:51.3540 | AN26: 3.0478778 | AO26: 799.77649 | AP26: 9.2001762 | AQ26: 0.13878061 | AR26: -2.9090972 | BC26: 0.015972222 | BD26: 12.094 | BG26: =BG25+0.5 -> 39230.5
AM27: 01/19/2026 10:53:51.8540 | AN27: 3.0496671 | AO27: 799.89832 | AP27: 9.6001673 | AQ27: 0.13878818 | AR27: -2.9108789 | BC27: 0.016666667 | BD27: 12.084 | BG27: =BG26+0.5 -> 39231
AM28: 01/19/2026 10:53:52.3540 | AN28: 3.0516145 | AO28: 800.06592 | AP28: 10.000167 | AQ28: 0.13880508 | AR28: -2.9128094 | BC28: 0.017361111 | BD28: 12.078 | BG28: =BG27+0.5 -> 39231.5
AM29: 01/19/2026 10:53:52.8540 | AN29: 3.0532529 | AO29: 800.08112 | AP29: 10.400167 | AQ29: 0.13881896 | AR29: -2.914434 | BC29: 0.018055556 | BD29: 12.072 | BG29: =BG28+0.5 -> 39232
AM30: 01/19/2026 10:53:53.3540 | AN30: 3.0551977 | AO30: 799.91364 | AP30: 10.80016 | AQ30: 0.13883558 | AR30: -2.916362 | BC30: 0.01875 | BD30: 12.065 | BG30: =BG29+0.5 -> 39232.5
AM31: 01/19/2026 10:53:53.8540 | AN31: 3.0573583 | AO31: 799.92883 | AP31: 11.200155 | AQ31: 0.13885553 | AR31: -2.9185028 | BC31: 0.019444444 | BD31: 12.058 | BG31: =BG30+0.5 -> 39233
AM32: 01/19/2026 10:53:54.3540 | AN32: 3.0595074 | AO32: 800.12689 | AP32: 11.600147 | AQ32: 0.13886529 | AR32: -2.9206421 | BC32: 0.020138889 | BD32: 12.051 | BG32: =BG31+0.5 -> 39233.5
AM33: 01/19/2026 10:53:54.8540 | AN33: 3.0606616 | AO33: 800.12689 | AP33: 12.000144 | AQ33: 0.13887636 | AR33: -2.9217851 | BC33: 0.020833333 | BD33: 12.045 | BG33: =BG32+0.5 -> 39234
AM34: 01/19/2026 10:53:55.3540 | AN34: 3.0630796 | AO34: 800.0202 | AP34: 12.400128 | AQ34: 0.13889654 | AR34: -2.9241831 | BC34: 0.021527778 | BD34: 12.039 | BG34: =BG33+0.5 -> 39234.5
... AM231: 01/19/2026 10:55:33.8540 | AN231: 3.2066128 | AO231: 800.06592 | AP231: 91.203979 | AQ231: 0.22399579 | AR231: -2.9826171 | BC231: 0.15833333 | BD231: 6.852 | BG231: =BG230+0.5 -> 39333
AM232: 01/19/2026 10:55:34.3540 | AN232: 3.2068582 | AO232: 799.88318 | AP232: 91.603981 | AQ232: 0.2246362 | AR232: -2.9822218 | BG232: =BG231+0.5 -> 39333.5
AM233: 01/19/2026 10:55:34.8540 | AN233: 3.206897 | AO233: 800.08118 | AP233: 92.00399 | AQ233: 0.22527687 | AR233: -2.9816201 | BG233: =BG232+0.5 -> 39334
AM234: 01/19/2026 10:55:35.3540 | AN234: 3.2069716 | AO234: 800.005 | AP234: 92.403999 | AQ234: 0.2259195 | AR234: -2.9810522 | BG234: =BG233+0.5 -> 39334.5
AM235: 01/19/2026 10:55:35.8540 | AN235: 3.2073162 | AO235: 800.03552 | AP235: 92.804001 | AQ235: 0.226542 | AR235: -2.9807742 | BG235: =BG234+0.5 -> 39335
AM236: 01/19/2026 10:55:36.3540 | AN236: 3.207294 | AO236: 799.94409 | AP236: 93.204002 | AQ236: 0.22716905 | AR236: -2.980125 | BG236: =BG235+0.5 -> 39335.5
...

Sheet Results
A1: Inj Namen | B1: Date | C1: Time | D1: Injection Time in s | E1: Current(mA) | F1: Cell Voltage | G1: Nitrogen (ppm) | H1: Total flow rate (ml/min) | I1: Temp Cathode (0C) | J1: Temp Anode (0C) | K1: Pressure (barg) | L1: CO (ppm) | M1: CO (ml/min) | N1: CO Q/t (mc/min) | O1: CO I (mA) | P1: CO FE (%) | Q1: CH4 (ppm) | R1: CH4 (ml/min) | S1: CH4 Q/t (mc/min) | T1: CH4 I (mA) | U1: CH4 FE (%) | V1: C2H4 (ppm) | W1: C2H4 (ml/min) | X1: C2H4 Q/t (mc/min) | Y1: C2H4 I (mA) | Z1: C2H4 FE (%) | AA1: H2 (ppm) | AB1: H2 (ml/min) | AC1: H2 Q/t (mc/min) | AD1: H2 I (mA) | AE1: H2 FE (%) | AF1: Total FE (%) | AH1: pH | AJ1: Feed Gas | AK1: Electrons Used CO | AL1: Electrons Used CH4 | AM1: Electrons Used C2H4 | AN1: Electrons Used H2
A2: ='Raw Data'!A3 -> 260119_FID01.CHR | B2: ='Raw Data'!B3 -> 46041 | C2: ='Raw Data'!C3 -> 0.45048611 | D2: =(HOUR(C2)*3600)+(MINUTE(C2)*60)+SECOND(C2) -> 38922 | E2: ='Raw Data'!BL5 -> #N/A | F2: ='Raw Data'!BM5 -> #N/A | G2: ='Experimental details'!$B$26 -> 246222 | H2: =10*G2*('Experimental details'!$B$22+'Experimental details'!$B$25)/'Experimental details'!$B$25/'Raw Data'!AJ3 -> #DIV/0! | I2: =LOOKUP(Results!$D2,'Raw Data'!BA:BA,'Raw Data'!AX:AX) -> 0 | J2: =LOOKUP(Results!$D2,'Raw Data'!BA:BA,'Raw Data'!AY:AY) -> 0 | K2: =LOOKUP(Results!$D2,'Raw Data'!BA:BA,'Raw Data'!AW:AW) -> 0 | L2: ='Raw Data'!G3 -> 0 | M2: =H2*L2/1000000 -> #DIV/0! | N2: =M2*AK2*96485/0.082057/298 -> #DIV/0! | O2: =N2/60 -> #DIV/0! | P2: =-O2*100/E2 -> #DIV/0! | Q2: ='Raw Data'!L3 -> 0 | R2: =Q2*H2/1000000 -> #DIV/0! | S2: =R2*AL2*96485/0.082057/298 -> #DIV/0! | T2: =S2/60 -> #DIV/0! | U2: =ABS(-T2*100/E2) -> #DIV/0! | V2: ='Raw Data'!Q3 -> 0 | W2: =H2*V2/1000000 -> #DIV/0! | X2: =W2*AM2*96485/0.082057/298 -> #DIV/0! | Y2: =X2/60 -> #DIV/0! | Z2: =ABS(-Y2*100/E2) -> #DIV/0! | AA2: ='Raw Data'!AE3 -> 0 | AB2: =AA2*H2/1000000 -> #DIV/0! | AC2: =AB2*AN2*96485/0.082057/298 -> #DIV/0! | AD2: =AC2/60 -> #DIV/0! | AE2: =ABS(-AD2*100/E2) -> #DIV/0! | AF2: =SUM(AE2+Z2+U2) -> #DIV/0! | AG2: Start | AJ2: ='Experimental details'!B21 -> CO | AK2: =IF(AJ2="CO",0,2) -> 0 | AL2: =IF(AJ2="CO",6,8) -> 6 | AM2: =IF(AJ2="CO",8,12) -> 8 | AN2: 2
A3: ='Raw Data'!A4 -> 260119_FID02.CHR | B3: ='Raw Data'!B3 -> 46041 | C3: ='Raw Data'!C4 -> 0.46298611 | D3: =(HOUR(C3)*3600)+(MINUTE(C3)*60)+SECOND(C3) -> 40002 | E3: ='Raw Data'!BL6 -> 800.17403 | F3: ='Raw Data'!BM6 -> 3.4915945 | G3: ='Experimental details'!$B$26 -> 246222 | H3: =10*G3*('Experimental details'!$B$22+'Experimental details'!$B$25)/'Experimental details'!$B$25/'Raw Data'!AJ4 -> 26.275919 | I3: =LOOKUP(Results!$D3,'Raw Data'!BA:BA,'Raw Data'!AX:AX) -> 0 | J3: =LOOKUP(Results!$D3,'Raw Data'!BA:BA,'Raw Data'!AY:AY) -> 0 | K3: =LOOKUP(Results!$D3,'Raw Data'!BA:BA,'Raw Data'!AW:AW) -> 0 | L3: ='Raw Data'!G4 -> 187280.24 | M3: =H3*L3/1000000 -> 4.9209603 | N3: =M3*AK3*96485/0.082057/298 -> 0 | O3: =N3/60 -> 0 | P3: =-O3*100/E3 -> 0 | Q3: ='Raw Data'!L4 -> 4608.6039 | R3: =Q3*H3/1000000 -> 0.1210953 | S3: =R3*AL3*96485/0.082057/298 -> 2866.8597 | T3: =S3/60 -> 47.780996 | U3: =ABS(-T3*100/E3) -> 5.9713255 | V3: ='Raw Data'!Q4 -> 4333.1607 | W3: =H3*V3/1000000 -> 0.11385778 | X3: =W3*AM3*96485/0.082057/298 -> 3594.0209 | Y3: =X3/60 -> 59.900348 | Z3: =ABS(-Y3*100/E3) -> 7.485915 | AA3: ='Raw Data'!AE4 -> 45707.419 | AB3: =AA3*H3/1000000 -> 1.2010044 | AC3: =AB3*AN3*96485/0.082057/298 -> 9477.6902 | AD3: =AC3/60 -> 157.9615 | AE3: =ABS(-AD3*100/E3) -> 19.740894 | AF3: =SUM(AE3+Z3+U3) -> 33.198134 | AG3: End | AJ3: ='Experimental details'!B21 -> CO | AK3: =IF(AJ3="CO",0,2) -> 0 | AL3: =IF(AJ3="CO",6,8) -> 6 | AM3: =IF(AJ3="CO",8,12) -> 8 | AN3: 2
A4: ='Raw Data'!A5 -> 260119_FID03.CHR | B4: ='Raw Data'!B3 -> 46041 | C4: ='Raw Data'!C5 -> 0.47548611 | D4: =(HOUR(C4)*3600)+(MINUTE(C4)*60)+SECOND(C4) -> 41082 | E4: ='Raw Data'!BL7 -> 800.07781 | F4: ='Raw Data'!BM7 -> 3.5121554 | G4: ='Experimental details'!$B$26 -> 246222 | H4: =10*G4*('Experimental details'!$B$22+'Experimental details'!$B$25)/'Experimental details'!$B$25/'Raw Data'!AJ5 -> 38.648235 | I4: =LOOKUP(Results!$D4,'Raw Data'!BA:BA,'Raw Data'!AX:AX) -> 0 | J4: =LOOKUP(Results!$D4,'Raw Data'!BA:BA,'Raw Data'!AY:AY) -> 0 | K4: =LOOKUP(Results!$D4,'Raw Data'!BA:BA,'Raw Data'!AW:AW) -> 0 | L4: ='Raw Data'!G5 -> 199973.76 | M4: =H4*L4/1000000 -> 7.7286327 | N4: =M4*AK4*96485/0.082057/298 -> 0 | O4: =N4/60 -> 0 | P4: =-O4*100/E4 -> 0 | Q4: ='Raw Data'!L5 -> 712.1224 | R4: =Q4*H4/1000000 -> 0.027522274 | S4: =R4*AL4*96485/0.082057/298 -> 651.57357 | T4: =S4/60 -> 10.85956 | U4: =ABS(-T4*100/E4) -> 1.3573129 | V4: ='Raw Data'!Q5 -> 11176.098 | W4: =H4*V4/1000000 -> 0.43193646 | X4: =W4*AM4*96485/0.082057/298 -> 13634.454 | Y4: =X4/60 -> 227.2409 | Z4: =ABS(-Y4*100/E4) -> 28.40235 | AA4: ='Raw Data'!AE5 -> 37833.812 | AB4: =AA4*H4/1000000 -> 1.4622101 | AC4: =AB4*AN4*96485/0.082057/298 -> 11538.986 | AD4: =AC4/60 -> 192.31644 | AE4: =ABS(-AD4*100/E4) -> 24.037217 | AF4: =SUM(AE4+Z4+U4) -> 53.79688 | AJ4: ='Experimental details'!B21 -> CO | AK4: =IF(AJ4="CO",0,2) -> 0 | AL4: =IF(AJ4="CO",6,8) -> 6 | AM4: =IF(AJ4="CO",8,12) -> 8 | AN4: 2
A5: ='Raw Data'!A6 -> 260119_FID04.CHR | B5: ='Raw Data'!B3 -> 46041 | C5: ='Raw Data'!C6 -> 0.48798611 | D5: =(HOUR(C5)*3600)+(MINUTE(C5)*60)+SECOND(C5) -> 42162 | E5: ='Raw Data'!BL8 -> 800.21341 | F5: ='Raw Data'!BM8 -> 3.4752615 | G5: ='Experimental details'!$B$26 -> 246222 | H5: =10*G5*('Experimental details'!$B$22+'Experimental details'!$B$25)/'Experimental details'!$B$25/'Raw Data'!AJ6 -> 39.213724 | I5: =LOOKUP(Results!$D5,'Raw Data'!BA:BA,'Raw Data'!AX:AX) -> 0 | J5: =LOOKUP(Results!$D5,'Raw Data'!BA:BA,'Raw Data'!AY:AY) -> 0 | K5: =LOOKUP(Results!$D5,'Raw Data'!BA:BA,'Raw Data'!AW:AW) -> 0 | L5: ='Raw Data'!G6 -> 202602.73 | M5: =H5*L5/1000000 -> 7.9448077 | N5: =M5*AK5*96485/0.082057/298 -> 0 | O5: =N5/60 -> 0 | P5: =-O5*100/E5 -> 0 | Q5: ='Raw Data'!L6 -> 0 | R5: =Q5*H5/1000000 -> 0 | S5: =R5*AL5*96485/0.082057/298 -> 0 | T5: =S5/60 -> 0 | U5: =ABS(-T5*100/E5) -> 0 | V5: ='Raw Data'!Q6 -> 13286.235 | W5: =H5*V5/1000000 -> 0.52100277 | X5: =W5*AM5*96485/0.082057/298 -> 16445.911 | Y5: =X5/60 -> 274.09851 | Z5: =ABS(-Y5*100/E5) -> 34.253176 | AA5: ='Raw Data'!AE6 -> 29940.476 | AB5: =AA5*H5/1000000 -> 1.1740776 | AC5: =AB5*AN5*96485/0.082057/298 -> 9265.1977 | AD5: =AC5/60 -> 154.41996 | AE5: =ABS(-AD5*100/E5) -> 19.297347 | AF5: =SUM(AE5+Z5+U5) -> 53.550524 | AJ5: ='Experimental details'!B21 -> CO | AK5: =IF(AJ5="CO",0,2) -> 0 | AL5: =IF(AJ5="CO",6,8) -> 6 | AM5: =IF(AJ5="CO",8,12) -> 8 | AN5: 2
A6: ='Raw Data'!A7 -> 260119_FID05.CHR | B6: ='Raw Data'!B3 -> 46041 | C6: ='Raw Data'!C7 -> 0.50049769 | D6: =(HOUR(C6)*3600)+(MINUTE(C6)*60)+SECOND(C6) -> 43243 | E6: ='Raw Data'!BL9 -> 800.05106 | F6: ='Raw Data'!BM9 -> 3.4649592 | G6: ='Experimental details'!$B$26 -> 246222 | H6: =10*G6*('Experimental details'!$B$22+'Experimental details'!$B$25)/'Experimental details'!$B$25/'Raw Data'!AJ7 -> 39.392957 | I6: =LOOKUP(Results!$D6,'Raw Data'!BA:BA,'Raw Data'!AX:AX) -> 0 | J6: =LOOKUP(Results!$D6,'Raw Data'!BA:BA,'Raw Data'!AY:AY) -> 0 | K6: =LOOKUP(Results!$D6,'Raw Data'!BA:BA,'Raw Data'!AW:AW) -> 0 | L6: ='Raw Data'!G7 -> 199856.64 | M6: =H6*L6/1000000 -> 7.8729443 | N6: =M6*AK6*96485/0.082057/298 -> 0 | O6: =N6/60 -> 0 | P6: =-O6*100/E6 -> 0 | Q6: ='Raw Data'!L7 -> 0 | R6: =Q6*H6/1000000 -> 0 | S6: =R6*AL6*96485/0.082057/298 -> 0 | T6: =S6/60 -> 0 | U6: =ABS(-T6*100/E6) -> 0 | V6: ='Raw Data'!Q7 -> 13608.757 | W6: =H6*V6/1000000 -> 0.53608917 | X6: =W6*AM6*96485/0.082057/298 -> 16922.126 | Y6: =X6/60 -> 282.03543 | Z6: =ABS(-Y6*100/E6) -> 35.252179 | AA6: ='Raw Data'!AE7 -> 30461.085 | AB6: =AA6*H6/1000000 -> 1.1999522 | AC6: =AB6*AN6*96485/0.082057/298 -> 9469.3866 | AD6: =AC6/60 -> 157.82311 | AE6: =ABS(-AD6*100/E6) -> 19.72663 | AF6: =SUM(AE6+Z6+U6) -> 54.978809 | AJ6: ='Experimental details'!B21 -> CO | AK6: =IF(AJ6="CO",0,2) -> 0 | AL6: =IF(AJ6="CO",6,8) -> 6 | AM6: =IF(AJ6="CO",8,12) -> 8 | AN6: 2
A7: ='Raw Data'!A8 -> 260119_FID06.CHR | B7: ='Raw Data'!B3 -> 46041 | C7: ='Raw Data'!C8 -> 0.51299769 | D7: =(HOUR(C7)*3600)+(MINUTE(C7)*60)+SECOND(C7) -> 44323 | E7: ='Raw Data'!BL10 -> 800.01689 | F7: ='Raw Data'!BM10 -> 3.4647597 | G7: ='Experimental details'!$B$26 -> 246222 | H7: =10*G7*('Experimental details'!$B$22+'Experimental details'!$B$25)/'Experimental details'!$B$25/'Raw Data'!AJ8 -> 39.605506 | I7: =LOOKUP(Results!$D7,'Raw Data'!BA:BA,'Raw Data'!AX:AX) -> 0 | J7: =LOOKUP(Results!$D7,'Raw Data'!BA:BA,'Raw Data'!AY:AY) -> 0 | K7: =LOOKUP(Results!$D7,'Raw Data'!BA:BA,'Raw Data'!AW:AW) -> 0 | L7: ='Raw Data'!G8 -> 197958.82 | M7: =H7*L7/1000000 -> 7.8402594 | N7: =M7*AK7*96485/0.082057/298 -> 0 | O7: =N7/60 -> 0 | P7: =-O7*100/E7 -> 0 | Q7: ='Raw Data'!L8 -> 0 | R7: =Q7*H7/1000000 -> 0 | S7: =R7*AL7*96485/0.082057/298 -> 0 | T7: =S7/60 -> 0 | U7: =ABS(-T7*100/E7) -> 0 | V7: ='Raw Data'!Q8 -> 13462.843 | W7: =H7*V7/1000000 -> 0.5332027 | X7: =W7*AM7*96485/0.082057/298 -> 16831.012 | Y7: =X7/60 -> 280.51687 | Z7: =ABS(-Y7*100/E7) -> 35.063868 | AA7: ='Raw Data'!AE8 -> 32905.255 | AB7: =AA7*H7/1000000 -> 1.3032293 | AC7: =AB7*AN7*96485/0.082057/298 -> 10284.394 | AD7: =AC7/60 -> 171.40657 | AE7: =ABS(-AD7*100/E7) -> 21.42537 | AF7: =SUM(AE7+Z7+U7) -> 56.489238 | AJ7: ='Experimental details'!B21 -> CO | AK7: =IF(AJ7="CO",0,2) -> 0 | AL7: =IF(AJ7="CO",6,8) -> 6 | AM7: =IF(AJ7="CO",8,12) -> 8 | AN7: 2
A8: ='Raw Data'!A9 -> 260119_FID07.CHR | B8: ='Raw Data'!B3 -> 46041 | C8: ='Raw Data'!C9 -> 0.52549769 | D8: =(HOUR(C8)*3600)+(MINUTE(C8)*60)+SECOND(C8) -> 45403 | E8: ='Raw Data'!BL11 -> 800.12648 | F8: ='Raw Data'!BM11 -> 3.4678321 | G8: ='Experimental details'!$B$26 -> 246222 | H8: =10*G8*('Experimental details'!$B$22+'Experimental details'!$B$25)/'Experimental details'!$B$25/'Raw Data'!AJ9 -> 39.693505 | I8: =LOOKUP(Results!$D8,'Raw Data'!BA:BA,'Raw Data'!AX:AX) -> 0 | J8: =LOOKUP(Results!$D8,'Raw Data'!BA:BA,'Raw Data'!AY:AY) -> 0 | K8: =LOOKUP(Results!$D8,'Raw Data'!BA:BA,'Raw Data'!AW:AW) -> 0 | L8: ='Raw Data'!G9 -> 196538.48 | M8: =H8*L8/1000000 -> 7.8013013 | N8: =M8*AK8*96485/0.082057/298 -> 0 | O8: =N8/60 -> 0 | P8: =-O8*100/E8 -> 0 | Q8: ='Raw Data'!L9 -> 0 | R8: =Q8*H8/1000000 -> 0 | S8: =R8*AL8*96485/0.082057/298 -> 0 | T8: =S8/60 -> 0 | U8: =ABS(-T8*100/E8) -> 0 | V8: ='Raw Data'!Q9 -> 13334.068 | W8: =H8*V8/1000000 -> 0.52927589 | X8: =W8*AM8*96485/0.082057/298 -> 16707.059 | Y8: =X8/60 -> 278.45098 | Z8: =ABS(-Y8*100/E8) -> 34.80087 | AA8: ='Raw Data'!AE9 -> 35279.112 | AB8: =AA8*H8/1000000 -> 1.4003516 | AC8: =AB8*AN8*96485/0.082057/298 -> 11050.833 | AD8: =AC8/60 -> 184.18054 | AE8: =ABS(-AD8*100/E8) -> 23.018928 | AF8: =SUM(AE8+Z8+U8) -> 57.819799 | AJ8: ='Experimental details'!B21 -> CO | AK8: =IF(AJ8="CO",0,2) -> 0 | AL8: =IF(AJ8="CO",6,8) -> 6 | AM8: =IF(AJ8="CO",8,12) -> 8 | AN8: 2
A9: ='Raw Data'!A10 -> 260119_FID08.CHR | B9: ='Raw Data'!B3 -> 46041 | C9: ='Raw Data'!C10 -> 0.53799769 | D9: =(HOUR(C9)*3600)+(MINUTE(C9)*60)+SECOND(C9) -> 46483 | E9: ='Raw Data'!BL12 -> 800.1406 | F9: ='Raw Data'!BM12 -> 3.4823129 | G9: ='Experimental details'!$B$26 -> 246222 | H9: =10*G9*('Experimental details'!$B$22+'Experimental details'!$B$25)/'Experimental details'!$B$25/'Raw Data'!AJ10 -> 40.093572 | I9: =LOOKUP(Results!$D9,'Raw Data'!BA:BA,'Raw Data'!AX:AX) -> 0 | J9: =LOOKUP(Results!$D9,'Raw Data'!BA:BA,'Raw Data'!AY:AY) -> 0 | K9: =LOOKUP(Results!$D9,'Raw Data'!BA:BA,'Raw Data'!AW:AW) -> 0 | L9: ='Raw Data'!G10 -> 195542.66 | M9: =H9*L9/1000000 -> 7.8400038 | N9: =M9*AK9*96485/0.082057/298 -> 0 | O9: =N9/60 -> 0 | P9: =-O9*100/E9 -> 0 | Q9: ='Raw Data'!L10 -> 0 | R9: =Q9*H9/1000000 -> 0 | S9: =R9*AL9*96485/0.082057/298 -> 0 | T9: =S9/60 -> 0 | U9: =ABS(-T9*100/E9) -> 0 | V9: ='Raw Data'!Q10 -> 13128.016 | W9: =H9*V9/1000000 -> 0.52634906 | X9: =W9*AM9*96485/0.082057/298 -> 16614.671 | Y9: =X9/60 -> 276.91118 | Z9: =ABS(-Y9*100/E9) -> 34.607815 | AA9: ='Raw Data'!AE10 -> 37810.504 | AB9: =AA9*H9/1000000 -> 1.5159582 | AC9: =AB9*AN9*96485/0.082057/298 -> 11963.138 | AD9: =AC9/60 -> 199.38563 | AE9: =ABS(-AD9*100/E9) -> 24.918825 | AF9: =SUM(AE9+Z9+U9) -> 59.52664 | AJ9: ='Experimental details'!B21 -> CO | AK9: =IF(AJ9="CO",0,2) -> 0 | AL9: =IF(AJ9="CO",6,8) -> 6 | AM9: =IF(AJ9="CO",8,12) -> 8 | AN9: 2
A10: ='Raw Data'!A11 -> 260119_FID09.CHR | B10: ='Raw Data'!B3 -> 46041 | C10: ='Raw Data'!C11 -> 0.55049769 | D10: =(HOUR(C10)*3600)+(MINUTE(C10)*60)+SECOND(C10) -> 47563 | E10: ='Raw Data'!BL13 -> 800.08376 | F10: ='Raw Data'!BM13 -> 3.5081074 | G10: ='Experimental details'!$B$26 -> 246222 | H10: =10*G10*('Experimental details'!$B$22+'Experimental details'!$B$25)/'Experimental details'!$B$25/'Raw Data'!AJ11 -> 40.17635 | I10: =LOOKUP(Results!$D10,'Raw Data'!BA:BA,'Raw Data'!AX:AX) -> 0 | J10: =LOOKUP(Results!$D10,'Raw Data'!BA:BA,'Raw Data'!AY:AY) -> 0 | K10: =LOOKUP(Results!$D10,'Raw Data'!BA:BA,'Raw Data'!AW:AW) -> 0 | L10: ='Raw Data'!G11 -> 193372.71 | M10: =H10*L10/1000000 -> 7.7690097 | N10: =M10*AK10*96485/0.082057/298 -> 0 | O10: =N10/60 -> 0 | P10: =-O10*100/E10 -> 0 | Q10: ='Raw Data'!L11 -> 0 | R10: =Q10*H10/1000000 -> 0 | S10: =R10*AL10*96485/0.082057/298 -> 0 | T10: =S10/60 -> 0 | U10: =ABS(-T10*100/E10) -> 0 | V10: ='Raw Data'!Q11 -> 12622.421 | W10: =H10*V10/1000000 -> 0.50712278 | X10: =W10*AM10*96485/0.082057/298 -> 16007.776 | Y10: =X10/60 -> 266.79627 | Z10: =ABS(-Y10*100/E10) -> 33.346043 | AA10: ='Raw Data'!AE11 -> 40963.263 | AB10: =AA10*H10/1000000 -> 1.6457544 | AC10: =AB10*AN10*96485/0.082057/298 -> 12987.421 | AD10: =AC10/60 -> 216.45702 | AE10: =ABS(-AD10*100/E10) -> 27.054295 | AF10: =SUM(AE10+Z10+U10) -> 60.400338 | AJ10: ='Experimental details'!B21 -> CO | AK10: =IF(AJ10="CO",0,2) -> 0 | AL10: =IF(AJ10="CO",6,8) -> 6 | AM10: =IF(AJ10="CO",8,12) -> 8 | AN10: 2
A11: ='Raw Data'!A12 -> 260119_FID10.CHR | B11: ='Raw Data'!B3 -> 46041 | C11: ='Raw Data'!C12 -> 0.56299769 | D11: =(HOUR(C11)*3600)+(MINUTE(C11)*60)+SECOND(C11) -> 48643 | E11: ='Raw Data'!BL14 -> 800.08598 | F11: ='Raw Data'!BM14 -> 3.5565616 | G11: ='Experimental details'!$B$26 -> 246222 | H11: =10*G11*('Experimental details'!$B$22+'Experimental details'!$B$25)/'Experimental details'!$B$25/'Raw Data'!AJ12 -> 40.444653 | I11: =LOOKUP(Results!$D11,'Raw Data'!BA:BA,'Raw Data'!AX:AX) -> 0 | J11: =LOOKUP(Results!$D11,'Raw Data'!BA:BA,'Raw Data'!AY:AY) -> 0 | K11: =LOOKUP(Results!$D11,'Raw Data'!BA:BA,'Raw Data'!AW:AW) -> 0 | L11: ='Raw Data'!G12 -> 192209.56 | M11: =H11*L11/1000000 -> 7.7738491 | N11: =M11*AK11*96485/0.082057/298 -> 0 | O11: =N11/60 -> 0 | P11: =-O11*100/E11 -> 0 | Q11: ='Raw Data'!L12 -> 0 | R11: =Q11*H11/1000000 -> 0 | S11: =R11*AL11*96485/0.082057/298 -> 0 | T11: =S11/60 -> 0 | U11: =ABS(-T11*100/E11) -> 0 | V11: ='Raw Data'!Q12 -> 12223.77 | W11: =H11*V11/1000000 -> 0.49438615 | X11: =W11*AM11*96485/0.082057/298 -> 15605.733 | Y11: =X11/60 -> 260.09556 | Z11: =ABS(-Y11*100/E11) -> 32.508451 | AA11: ='Raw Data'!AE12 -> 44957.949 | AB11: =AA11*H11/1000000 -> 1.8183087 | AC11: =AB11*AN11*96485/0.082057/298 -> 14349.128 | AD11: =AC11/60 -> 239.15213 | AE11: =ABS(-AD11*100/E11) -> 29.890804 | AF11: =SUM(AE11+Z11+U11) -> 62.399255 | AJ11: ='Experimental details'!B21 -> CO | AK11: =IF(AJ11="CO",0,2) -> 0 | AL11: =IF(AJ11="CO",6,8) -> 6 | AM11: =IF(AJ11="CO",8,12) -> 8 | AN11: 2
A12: ='Raw Data'!A13 -> 260119_FID11.CHR | B12: ='Raw Data'!B3 -> 46041 | C12: ='Raw Data'!C13 -> 0.57550926 | D12: =(HOUR(C12)*3600)+(MINUTE(C12)*60)+SECOND(C12) -> 49724 | E12: ='Raw Data'!BL15 -> 800.1209 | F12: ='Raw Data'!BM15 -> 3.5934131 | G12: ='Experimental details'!$B$26 -> 246222 | H12: =10*G12*('Experimental details'!$B$22+'Experimental details'!$B$25)/'Experimental details'!$B$25/'Raw Data'!AJ13 -> 40.963817 | I12: =LOOKUP(Results!$D12,'Raw Data'!BA:BA,'Raw Data'!AX:AX) -> 0 | J12: =LOOKUP(Results!$D12,'Raw Data'!BA:BA,'Raw Data'!AY:AY) -> 0 | K12: =LOOKUP(Results!$D12,'Raw Data'!BA:BA,'Raw Data'!AW:AW) -> 0 | L12: ='Raw Data'!G13 -> 190466.17 | M12: =H12*L12/1000000 -> 7.8022212 | N12: =M12*AK12*96485/0.082057/298 -> 0 | O12: =N12/60 -> 0 | P12: =-O12*100/E12 -> 0 | Q12: ='Raw Data'!L13 -> 0 | R12: =Q12*H12/1000000 -> 0 | S12: =R12*AL12*96485/0.082057/298 -> 0 | T12: =S12/60 -> 0 | U12: =ABS(-T12*100/E12) -> 0 | V12: ='Raw Data'!Q13 -> 11349.335 | W12: =H12*V12/1000000 -> 0.46491206 | X12: =W12*AM12*96485/0.082057/298 -> 14675.358 | Y12: =X12/60 -> 244.5893 | Z12: =ABS(-Y12*100/E12) -> 30.569042 | AA12: ='Raw Data'!AE13 -> 50672.906 | AB12: =AA12*H12/1000000 -> 2.0757556 | AC12: =AB12*AN12*96485/0.082057/298 -> 16380.763 | AD12: =AC12/60 -> 273.01271 | AE12: =ABS(-AD12*100/E12) -> 34.121432 | AF12: =SUM(AE12+Z12+U12) -> 64.690475 | AJ12: ='Experimental details'!B21 -> CO | AK12: =IF(AJ12="CO",0,2) -> 0 | AL12: =IF(AJ12="CO",6,8) -> 6 | AM12: =IF(AJ12="CO",8,12) -> 8 | AN12: 2
A13: ='Raw Data'!A14 -> 260119_FID12.CHR | B13: ='Raw Data'!B3 -> 46041 | C13: ='Raw Data'!C14 -> 0.58800926 | D13: =(HOUR(C13)*3600)+(MINUTE(C13)*60)+SECOND(C13) -> 50804 | E13: ='Raw Data'!BL16 -> 800.1209 | F13: ='Raw Data'!BM16 -> 3.5934131 | G13: ='Experimental details'!$B$26 -> 246222 | H13: =10*G13*('Experimental details'!$B$22+'Experimental details'!$B$25)/'Experimental details'!$B$25/'Raw Data'!AJ14 -> 39.679984 | I13: =LOOKUP(Results!$D13,'Raw Data'!BA:BA,'Raw Data'!AX:AX) -> 0 | J13: =LOOKUP(Results!$D13,'Raw Data'!BA:BA,'Raw Data'!AY:AY) -> 0 | K13: =LOOKUP(Results!$D13,'Raw Data'!BA:BA,'Raw Data'!AW:AW) -> 0 | L13: ='Raw Data'!G14 -> 193392.33 | M13: =H13*L13/1000000 -> 7.6738046 | N13: =M13*AK13*96485/0.082057/298 -> 0 | O13: =N13/60 -> 0 | P13: =-O13*100/E13 -> 0 | Q13: ='Raw Data'!L14 -> 0 | R13: =Q13*H13/1000000 -> 0 | S13: =R13*AL13*96485/0.082057/298 -> 0 | T13: =S13/60 -> 0 | U13: =ABS(-T13*100/E13) -> 0 | V13: ='Raw Data'!Q14 -> 3767.7205 | W13: =H13*V13/1000000 -> 0.14950309 | X13: =W13*AM13*96485/0.082057/298 -> 4719.1965 | Y13: =X13/60 -> 78.653275 | Z13: =ABS(-Y13*100/E13) -> 9.8301737 | AA13: ='Raw Data'!AE14 -> 19942.181 | AB13: =AA13*H13/1000000 -> 0.79130545 | AC13: =AB13*AN13*96485/0.082057/298 -> 6244.563 | AD13: =AC13/60 -> 104.07605 | AE13: =ABS(-AD13*100/E13) -> 13.00754 | AF13: =SUM(AE13+Z13+U13) -> 22.837714 | AJ13: ='Experimental details'!B21 -> CO | AK13: =IF(AJ13="CO",0,2) -> 0 | AL13: =IF(AJ13="CO",6,8) -> 6 | AM13: =IF(AJ13="CO",8,12) -> 8 | AN13: 2
A14: ='Raw Data'!A15 -> 260119_FID13.CHR | B14: ='Raw Data'!B3 -> 46041 | C14: ='Raw Data'!C15 -> 0.60050926 | D14: =(HOUR(C14)*3600)+(MINUTE(C14)*60)+SECOND(C14) -> 51884 | E14: ='Raw Data'!BL17 -> 800.1209 | F14: ='Raw Data'!BM17 -> 3.5934131 | G14: ='Experimental details'!$B$26 -> 246222 | H14: =10*G14*('Experimental details'!$B$22+'Experimental details'!$B$25)/'Experimental details'!$B$25/'Raw Data'!AJ15 -> 39.984723 | I14: =LOOKUP(Results!$D14,'Raw Data'!BA:BA,'Raw Data'!AX:AX) -> 0 | J14: =LOOKUP(Results!$D14,'Raw Data'!BA:BA,'Raw Data'!AY:AY) -> 0 | K14: =LOOKUP(Results!$D14,'Raw Data'!BA:BA,'Raw Data'!AW:AW) -> 0 | L14: ='Raw Data'!G15 -> 193848.03 | M14: =H14*L14/1000000 -> 7.7509597 | N14: =M14*AK14*96485/0.082057/298 -> 0 | O14: =N14/60 -> 0 | P14: =-O14*100/E14 -> 0 | Q14: ='Raw Data'!L15 -> 0 | R14: =Q14*H14/1000000 -> 0 | S14: =R14*AL14*96485/0.082057/298 -> 0 | T14: =S14/60 -> 0 | U14: =ABS(-T14*100/E14) -> 0 | V14: ='Raw Data'!Q15 -> 0 | W14: =H14*V14/1000000 -> 0 | X14: =W14*AM14*96485/0.082057/298 -> 0 | Y14: =X14/60 -> 0 | Z14: =ABS(-Y14*100/E14) -> 0 | AA14: ='Raw Data'!AE15 -> 0 | AB14: =AA14*H14/1000000 -> 0 | AC14: =AB14*AN14*96485/0.082057/298 -> 0 | AD14: =AC14/60 -> 0 | AE14: =ABS(-AD14*100/E14) -> 0 | AF14: =SUM(AE14+Z14+U14) -> 0 | AJ14: ='Experimental details'!B21 -> CO | AK14: =IF(AJ14="CO",0,2) -> 0 | AL14: =IF(AJ14="CO",6,8) -> 6 | AM14: =IF(AJ14="CO",8,12) -> 8 | AN14: 2
A15: ='Raw Data'!A16 -> 260119_FID14.CHR | B15: ='Raw Data'!B3 -> 46041 | C15: ='Raw Data'!C16 -> 0.61300926 | D15: =(HOUR(C15)*3600)+(MINUTE(C15)*60)+SECOND(C15) -> 52964 | E15: ='Raw Data'!BL18 -> 800.1209 | F15: ='Raw Data'!BM18 -> 3.5934131 | G15: ='Experimental details'!$B$26 -> 246222 | H15: =10*G15*('Experimental details'!$B$22+'Experimental details'!$B$25)/'Experimental details'!$B$25/'Raw Data'!AJ16 -> 39.999894 | I15: =LOOKUP(Results!$D15,'Raw Data'!BA:BA,'Raw Data'!AX:AX) -> 0 | J15: =LOOKUP(Results!$D15,'Raw Data'!BA:BA,'Raw Data'!AY:AY) -> 0 | K15: =LOOKUP(Results!$D15,'Raw Data'!BA:BA,'Raw Data'!AW:AW) -> 0 | L15: ='Raw Data'!G16 -> 193767.98 | M15: =H15*L15/1000000 -> 7.7506985 | N15: =M15*AK15*96485/0.082057/298 -> 0 | O15: =N15/60 -> 0 | P15: =-O15*100/E15 -> 0 | Q15: ='Raw Data'!L16 -> 0 | R15: =Q15*H15/1000000 -> 0 | S15: =R15*AL15*96485/0.082057/298 -> 0 | T15: =S15/60 -> 0 | U15: =ABS(-T15*100/E15) -> 0 | V15: ='Raw Data'!Q16 -> 0 | W15: =H15*V15/1000000 -> 0 | X15: =W15*AM15*96485/0.082057/298 -> 0 | Y15: =X15/60 -> 0 | Z15: =ABS(-Y15*100/E15) -> 0 | AA15: ='Raw Data'!AE16 -> 0 | AB15: =AA15*H15/1000000 -> 0 | AC15: =AB15*AN15*96485/0.082057/298 -> 0 | AD15: =AC15/60 -> 0 | AE15: =ABS(-AD15*100/E15) -> 0 | AF15: =SUM(AE15+Z15+U15) -> 0 | AJ15: ='Experimental details'!B21 -> CO | AK15: =IF(AJ15="CO",0,2) -> 0 | AL15: =IF(AJ15="CO",6,8) -> 6 | AM15: =IF(AJ15="CO",8,12) -> 8 | AN15: 2

Sheet Recipe Mappings
B1: AR_Ir_SD_0001 | C1: AR_Ir_SD_0002 | H1: CR_Cu_SD_0001 | I1: CR_Cu_SD_0002 | J1: CR_Cu_SD_0003 | K1: CR_Cu_UN_0001 | L1: CR_Ag_SD_0001
A2: Recipe Name | B2: Ir | C2: Ir on Titanium | H2: Cu 9% Nafion | I2: Cu 0% Nafion | J2: Cu 1xNafion | K2: Cu spray nozzle | L2: Silver
A3: Element | B3: Ir | C3: Ir | H3: Cu | I3: Cu | J3: Cu | K3: Cu | L3: Ag
A4: Element Mass (mg) | B4: 190 | C4: 190 | H4: 200 | I4: 200 | J4: 200 | K4: 200
A5: Solvent 1 Type | B5: Isopropanol | C5: H20 | H5: Isopropanol | I5: Isopropanol | J5: Isopropanol | K5: Isopropanol | L5: Isopropanol
A6: Solvent 1 Volume (ml) | B6: 10 | C6: 4.75 | H6: 10 | I6: 10 | J6: 10 | K6: 20 | L6: 20
A7: Solvent 2 Type | B7: H2O | C7: Isopropanol | H7: H2O | I7: H2O | J7: H2O | K7: H2O | L7: H2O
A8: Solvent 2 Volume (ml) | B8: 0 | C8: 4.75 | H8: 10 | I8: 10 | J8: 10 | K8: 20 | L8: 20
A9: Ionomer 1 Type | B9: Sustanion XA-9 5% in Ethanol | C9: Sustanion XA-9 5% in Ethanol | H9: Nafion perfluorinated resin solution | J9: Nafion perfluorinated resin solution | K9: Sustanion | L9: PTFE
A10: Ionomer 1 Mass (mg) | B10: 670 | C10: 670 | H10: 420 | J10: 600 | K10: 20 | L10: 20
A11: Ionomer 2 Type | L11: Sustanion XA-9 5% in Ethanol
A12: Ionomer 2 Mass (mg) | L12: 30
A13: Deposition Method | B13: Spray Dep | C13: Spray Dep | H13: Spray Dep | I13: Spray Dep | J13: Spray Dep | K13: Ultrasonic Nozzle | L13: Spray Dep
A14: Deposition Temperature (°C) | B14: 185 | C14: 180 | H14: 185 | I14: 185 | J14: 185 | K14: 185 | L14: 185
A15: N2 Deposition Pressure (bar) | B15: 2 | C15: 2 | H15: 2 | I15: 2 | J15: 2 | K15: 1.5 | L15: 2
A16: Substrate | B16: Platinum | C16: Titanium | H16: Freudenberg H23C6 | I16: Freudenberg H23C6 | J16: Freudenberg H23C6 | K16: GDL | L16: Freudenberg H23C6
A17: Substrate Dimension | B17: 6 frits | C17: frit | H17: 14 x 4 | I17: 14 x 4 | J17: 14 x 4 | K17: 250 micron | L17: 4 x 14
A18: Substrate Total Area (cm²) | B18: 48 | H18: 54 | I18: 54 | J18: 54 | K18: 8 | L18: 56
A19: Substrate Cleaning
A20: Mass Loading (mg/cm2) | H20: 1 | I20: 1 | J20: 1 | K20: 1 | L20: 1
A21: Recipe Remarks
